Workbook
Name MAN_HOURS: 'SBS Estimate'!$F$49

Sheet SBS Estimate
C1: Job Name: | D1: Salthill
C2: Type: | D2: 2 Ply SBS Stripping Torch
C3: Roof System: 3182 ft2 - MD, 1/2" Dens, HPR Base, StressPly IV Plus Cap, Drainage,Re-Use Rubber Mat, Re-Use 1" + 2" XPS, Grass by Others
A5: Quantity | B5: Type | C5: Descriptions | D5: Price | E5: Total
E6: =A6*D6 -> 0 | F6: 31.8 | G6: SQS
A7: 100 | B7: SHEETS | C7: 1/2" DENSDECK PRIME | D7: 36.5 | E7: =A7*D7 -> 3650
A8: 11 | B8: BOX | C8: INSUL-LOCK FOAM ADHESIVE | D8: 880 | E8: =A8*D8 -> 9680
E9: =A9*D9 -> 0
A10: 34 | B10: ROLLS | C10: HPR BASE (97 FT2) - FIELD | D10: 538 | E10: =A10*D10 -> 18292
A11: 1 | B11: PAILS | C11: PRO-STOP FR PRIMER | D11: 939 | E11: =A11*D11 -> 939
A12: 5 | B12: ROLLS | C12: SA BASE IV - STRIPPING (97 FT2) | D12: 515 | E12: =A12*D12 -> 2575
A13: 7 | E13: =A13*D13 -> 0
A14: 44 | B14: ROLLS | C14: STRESSPLY IV PLUS CAP (75 FT2) - FIELD | D14: 599 | E14: =A14*D14 -> 26356
A15: 6 | B15: ROLLS | C15: STRESSPLY IV PLUS CAP (75 FT2) - STRIPPING | D15: 599 | E15: =A15*D15 -> 3594
E16: =A16*D16 -> 0
A17: 11 | B17: ROLLS | C17: SOPRADRAIN 10-G (300 FT2) | D17: 226.5 | E17: =A17*D17 -> 2491.5
E18: =A18*D18 -> 0
A19: 285 | B19: FEET | C19: CANT | D19: 2.5 | E19: =A19*D19 -> 712.5
A20: 29 | B20: LENGTH | C20: TERM BAR | D20: 12.5 | E20: =A20*D20 -> 362.5
A21: 24 | B21: ROLLS | C21: FIRETAPE | D21: 28 | E21: =A21*D21 -> 672
E22: =A22*D22 -> 0
E23: =A23*D23 -> 0
E24: =A24*D24 -> 0
E25: =A25*D25 -> 0
A26: 1 | B26: BAGS | C26: SEAL-TITE SINGLE PART STPE PITCH POCKET (4) | D26: 508 | E26: =A26*D26 -> 508
B27: CASE | C27: TUFF STUFF MS SILICONE SEALANT (24 / CASE) | D27: 790 | E27: =A27*D27 -> 0
B28: EACH | C28: DRAINS C/W U-FLOW | D28: 550 | E28: =A28*D28 -> 0
A29: 3 | B29: PAILS | C29: GARLA-FLEX (30 FT2 / PL) - VERTICAL SEAMS | D29: 542 | E29: =A29*D29 -> 1626
A30: 1 | B30: ROLLS | C30: 6" GARMESH - 150' - VERTICAL SEAMS | D30: 105 | E30: =A30*D30 -> 105
E31: =A31*D31 -> 0
E32: =A32*D32 -> 0
E33: =A33*D33 -> 0
A34: 10 | B34: SHEETS | C34: 24 GAUGE PREFINISHED | D34: 75 | E34: =A34*D34 -> 750
B35: SHEETS | C35: 26 GAUGE GALV | D35: 50 | E35: =A35*D35 -> 0
A36: 1 | B36: LOADS | C36: FREIGHT - MATERIALS | D36: 1150 | E36: =A36*D36 -> 1150
A37: =F6 -> 31.8 | B37: SQS | C37: MISC | D37: 30 | E37: =A37*D37 -> 954
E38: =SUM(E6:E37) -> 74417.5
D39: SQS | E39: ft2 | F39: m2
D40: =F6 -> 31.8 | E40: =E38/D40/100 -> 23.40173 | F40: =D40/10.76389*100 -> 295.43223
A42: LABOUR
...

Sheet Job Codes
B1: CODE | C1: DESCRIPTION | D1: AMOUNT
B2: 7080 M | C2: Roofing Materials | D2: =SUM('SBS Estimate'!E38)-('SBS Estimate'!E36) -> 73267.5
B3: 1440 M | C3: Freight Materials | D3: ='SBS Estimate'!E36 -> 1150
B4: 7080 L | C4: Roofing Labour | D4: =SUM('SBS Estimate'!E62-'Job Codes'!D5) -> 30868.028
B5: 1410 L | C5: Metal Labour | D5: =SUM('SBS Estimate'!E53+'SBS Estimate'!E54)*('SBS Estimate'!D57+1)*('SBS Estimate'!D59+1)*('SBS Estimate'!D61+1) -> 3011.5594
B6: 1210 O | C6: Job Truck & Fuel | D6: ='SBS Estimate'!E67 -> 1950
B7: 1425 O | C7: Room & Board | D7: ='SBS Estimate'!E68 -> 0
B8: 1280 E | C8: Crane / Forklifts / Lifts | D8: ='SBS Estimate'!E69 -> 1770
B9: 1150 O | C9: Bins, Dumping & Disposal | D9: ='SBS Estimate'!E70 -> 2300
B10: 1163 O | C10: Roofing Warranty | D10: =SUM('SBS Estimate'!E66+'SBS Estimate'!E71) -> 0
B11: 15000 S | C11: Mechanical Sub | D11: ='SBS Estimate'!E72 -> 15000
B12: 16000 S | C12: Vacuum Sub | D12: ='SBS Estimate'!E73 -> 5000
B13: 1140 E | C13: Safety Equipment & Training | D13: ='SBS Estimate'!E74 -> 318
B14: 1270 O | C14: Consumables, Tools, Jobshacks | D14: ='SBS Estimate'!E75+'SBS Estimate'!E77+'SBS Estimate'!E78 -> 1268
B15: 7095 O | C15: Propane | D15: ='SBS Estimate'!E76 -> 690
B16: 1120 O | C16: Insurance | D16: ='SBS Estimate'!E83 -> 3666.9384
C17: Profit | D17: ='SBS Estimate'!E82 -> 46753.831
B18: 99999 R | C18: Revenue / Contract Amount | D18: ='SBS Estimate'!E84 -> 187013.86

Sheet Schedule of Values
B2: Trucraft Roofing (2005) Ltd.
B3: Job Name: | C3: Triovest
B4: Schedule Of Values | D4: Job# | I4: 42035
B5: Claim # 1
B6: ORIGINAL CONTRACT VALUE: | C6: ='SBS Estimate'!E84 -> 187013.86 | D6: Amount | E6: % Complete | F6: TOTAL CLAIM | G6: PREV CLAIMS | H6: THIS CLAIM | I6: % To claim | J6: Left to Claim
B9: MATERIALS
B10: Roofing | D10: =SUM('SBS Estimate'!E6:E33)*('SBS Estimate'!F82)+SUM('SBS Estimate'!E6:E33) -> 89454.515 | E10: 0 | F10: =D10*E10 -> 0 | G10: 0 | H10: =D10*E10-G10 -> 0 | I10: =1-E10 -> 1 | J10: =I10*D10 -> 89454.515
B11: Metal | D11: =SUM('SBS Estimate'!E34:E35)*('SBS Estimate'!F82)+SUM('SBS Estimate'!E34:E35) -> 937.50147 | E11: 0 | F11: =D11*E11 -> 0 | G11: 0 | H11: =D11*E11-G11 -> 0 | I11: =1-E11 -> 1 | J11: =I11*D11 -> 937.50147
B12: Freight | D12: =SUM('SBS Estimate'!E36)*('SBS Estimate'!F82)+('SBS Estimate'!E36) -> 1437.5023 | E12: 0 | F12: =D12*E12 -> 0 | G12: 0 | H12: =D12*E12-G12 -> 0 | I12: =1-E12 -> 1 | J12: =I12*D12 -> 1437.5023
B14: LABOUR
B15: Set-Up | D15: ='SBS Estimate'!E44*('SBS Estimate'!D57+1)*('SBS Estimate'!D59+1)*('SBS Estimate'!D61+1)*('SBS Estimate'!F82+1) -> 3753.0684 | E15: 0 | F15: =D15*E15 -> 0 | G15: 0 | H15: =D15*E15-G15 -> 0 | I15: =1-E15 -> 1 | J15: =I15*D15 -> 3753.0684
B16: Demolition | D16: ='SBS Estimate'!E45*('SBS Estimate'!D57+1)*('SBS Estimate'!D59+1)*('SBS Estimate'!D61+1)*('SBS Estimate'!F82+1) -> 7506.1368 | E16: 0 | F16: =D16*E16 -> 0 | G16: 0 | H16: =D16*E16-G16 -> 0 | I16: =1-E16 -> 1 | J16: =I16*D16 -> 7506.1368
B17: Install - Roofing | D17: =SUM('SBS Estimate'!E46:E56)*('SBS Estimate'!D57+1)*('SBS Estimate'!D59+1)*('SBS Estimate'!D61+1)*('SBS Estimate'!F82+1)-(D18) -> 27325.891 | E17: 0 | F17: =D17*E17 -> 0 | G17: 0 | H17: =D17*E17-G17 -> 0 | I17: =1-E17 -> 1 | J17: =I17*D17 -> 27325.891
B18: Install - Metal | D18: =SUM('SBS Estimate'!E53:E54)*('SBS Estimate'!D57+1)*('SBS Estimate'!D59+1)*('SBS Estimate'!D61+1)*('SBS Estimate'!F82+1) -> 3764.4551 | E18: 0 | F18: =D18*E18 -> 0 | G18: 0 | H18: =D18*E18-G18 -> 0 | I18: =1-E18 -> 1 | J18: =I18*D18 -> 3764.4551
B20: GENERAL
B21: Insurance | D21: ='SBS Estimate'!E83*2 -> 7333.8767 | E21: 0 | F21: =D21*E21 -> 0 | G21: 0 | H21: =D21*E21-G21 -> 0 | I21: =1-E21 -> 1 | J21: =I21*D21 -> 7333.8767
B22: Crane / Forklift / Zoom Boom | D22: ='SBS Estimate'!E69 -> 1770 | E22: 0 | F22: =D22*E22 -> 0 | G22: 0 | H22: =D22*E22-G22 -> 0 | I22: =1-E22 -> 1 | J22: =I22*D22 -> 1770
B23: Waste Disposal | D23: ='SBS Estimate'!E70 -> 2300 | E23: 0 | F23: =D23*E23 -> 0 | G23: 0 | H23: =D23*E23-G23 -> 0 | I23: =1-E23 -> 1 | J23: =I23*D23 -> 2300
B24: Fuel / Propane | D24: =SUM('SBS Estimate'!E67+'SBS Estimate'!E76) -> 2640 | E24: 0 | F24: =D24*E24 -> 0 | G24: 0 | H24: =D24*E24-G24 -> 0 | I24: =1-E24 -> 1 | J24: =I24*D24 -> 2640
B25: Vacuum | D25: ='SBS Estimate'!E73*('SBS Estimate'!F82+1) -> 6250.0098 | E25: 0 | F25: =D25*E25 -> 0 | G25: 0 | H25: =D25*E25-G25 -> 0 | I25: =1-E25 -> 1 | J25: =I25*D25 -> 6250.0098
B26: Mechanical / Electrical | D26: ='SBS Estimate'!E72*('SBS Estimate'!F82+1) -> 18750.029 | E26: 0 | F26: =D26*E26 -> 0 | G26: 0 | H26: =D26*E26-G26 -> 0 | I26: =1-E26 -> 1 | J26: =I26*D26 -> 18750.029
B27: Room and Board | D27: ='SBS Estimate'!E68 -> 0 | E27: 0 | F27: =D27*E27 -> 0 | G27: 0 | H27: =D27*E27-G27 -> 0 | I27: =1-E27 -> 1 | J27: =I27*D27 -> 0
B28: Security / Safety / Communications | D28: =SUM('SBS Estimate'!E74:E75) -> 636 | E28: 0 | F28: =D28*E28 -> 0 | G28: 0 | H28: =D28*E28-G28 -> 0 | I28: =1-E28 -> 1 | J28: =I28*D28 -> 636
B29: Warranty and Inspections | D29: =SUM('SBS Estimate'!E66+'SBS Estimate'!E71) -> 0 | E29: 0 | F29: =D29*E29 -> 0 | G29: 0 | H29: =D29*E29-G29 -> 0 | I29: =1-E29 -> 1 | J29: =I29*D29 -> 0
B30: Bonding | D30: ='SBS Estimate'!E79 -> 0 | E30: 0 | F30: =D30*E30 -> 0 | G30: 0 | H30: =D30*E30-G30 -> 0 | I30: =1-E30 -> 1 | J30: =I30*D30 -> 0
B31: Overhead | D31: =C6-SUM(D10:D30) -> 13154.871 | E31: 0 | F31: =D31*E31 -> 0 | G31: 0 | H31: =D31*E31-G31 -> 0 | I31: =1-E31 -> 1 | J31: =I31*D31 -> 13154.871
B34: Change Orders:
D35: 0 | E35: 0 | F35: =D35*E35 -> 0 | G35: 0 | H35: =D35*E35-G35 -> 0 | I35: =1-E35 -> 1 | J35: =I35*D35 -> 0
D36: 0 | E36: 0 | F36: =D36*E36 -> 0 | G36: 0 | H36: =D36*E36-G36 -> 0 | I36: =1-E36 -> 1 | J36: =I36*D36 -> 0
D37: 0 | E37: 0 | F37: =D37*E37 -> 0 | G37: 0 | H37: =D37*E37-G37 -> 0 | I37: =1-E37 -> 1 | J37: =I37*D37 -> 0
B39: TOTAL CONTRACT VALUE | D39: =SUM(D10:D37) -> 187013.86 | F39: =SUM(F10:F37) -> 0 | G39: =SUM(G10:G37) -> 0 | H39: =SUM(H10:H37) -> 0 | J39: =SUM(J10:J37) -> 187013.86
B40: Less holdback @ 10% | D40: =-10%*D39 -> -18701.386 | F40: =-10%*F39 -> 0 | G40: =-10%*G39 -> 0 | H40: =-10%*H39 -> 0 | J40: =-10%*J39 -> -18701.386
B41: Sub total | D41: =SUM(D39:D40) -> 168312.47 | F41: =SUM(F39:F40) -> 0 | G41: =SUM(G39:G40) -> 0 | H41: =SUM(H39:H40) -> 0 | J41: =SUM(J39:J40) -> 168312.47
B42: GST @ 5% | D42: =D41*0.05 -> 8415.6235 | F42: =F41*0.05 -> 0 | G42: =G41*0.05 -> 0 | H42: =H41*0.05 -> 0 | J42: =J41*0.05 -> 8415.6235
B43: Total Claim | D43: =SUM(D41:D42) -> 176728.09 | E43: =F43/D43 -> 0 | F43: =SUM(F41:F42) -> 0 | G43: =SUM(G41:G42) -> 0 | H43: =SUM(H41:H42) -> 0 | I43: =1-E43 -> 1 | J43: =SUM(J41:J42) -> 176728.09
